Workbook
Name cricket_data: raw_data!$B$1:$N$61

Sheet raw_data
A1: player_id | B1: Player_Name | C1: Role | D1: Matches | E1: Runs | F1: Balls_Faced | G1: 100s | H1: 50s | I1: Wickets | J1: Overs_Bowled | K1: Runs_Conceded | L1: Catches | M1: Stumpings | N1: Auction_Price_Cr
A2: ="P"&TEXT(ROW()-1,"000") -> P001 | B2: Aarav Shekhawat | C2: Batsman | D2: 12 | E2: 512 | F2: 378 | G2: 1 | H2: 4 | I2: 1 | J2: 2 | K2: 18 | L2: 8 | M2: 0 | N2: 14.5
A3: ="P"&TEXT(ROW()-1,"000") -> P002 | B3: Dev Malhotra | C3: Batsman | D3: 11 | E3: 468 | F3: 340 | G3: 0 | H3: 4 | I3: 0 | J3: 1 | K3: 12 | L3: 7 | M3: 0 | N3: 12.2
A4: ="P"&TEXT(ROW()-1,"000") -> P003 | B4: Rishan Bedi | C4: Batsman | D4: 10 | E4: 355 | F4: 250 | G4: 0 | H4: 3 | I4: 0 | J4: 0 | K4: 0 | L4: 6 | M4: 0 | N4: 8.5
A5: ="P"&TEXT(ROW()-1,"000") -> P004 | B5: Kunal Purohit | C5: Batsman | D5: 9 | E5: 298 | F5: 210 | G5: 0 | H5: 2 | I5: 0 | J5: 0 | K5: 0 | L5: 5 | M5: 0 | N5: 6.2
A6: ="P"&TEXT(ROW()-1,"000") -> P005 | B6: Yash Vartak | C6: Batsman | D6: 13 | E6: 540 | F6: 402 | G6: 1 | H6: 5 | I6: 2 | J6: 3 | K6: 25 | L6: 10 | M6: 0 | N6: 17.3
A7: ="P"&TEXT(ROW()-1,"000") -> P006 | B7: Manan Kapoor | C7: Batsman | D7: 8 | E7: 265 | F7: 185 | G7: 0 | H7: 2 | I7: 0 | J7: 0 | K7: 0 | L7: 4 | M7: 0 | N7: 5.5
A8: ="P"&TEXT(ROW()-1,"000") -> P007 | B8: Rajat Talwar | C8: Batsman | D8: 14 | E8: 525 | F8: 415 | G8: 1 | H8: 4 | I8: 1 | J8: 2 | K8: 20 | L8: 9 | M8: 0 | N8: 15.6
A9: ="P"&TEXT(ROW()-1,"000") -> P008 | B9: Nikhil Arora | C9: Batsman | D9: 12 | E9: 410 | F9: 305 | G9: 0 | H9: 3 | I9: 0 | J9: 0 | K9: 0 | L9: 6 | M9: 0 | N9: 9.2
A10: ="P"&TEXT(ROW()-1,"000") -> P009 | B10: Samar Khatri | C10: Batsman | D10: 10 | E10: 280 | F10: 195 | G10: 0 | H10: 2 | I10: 0 | J10: 0 | K10: 0 | L10: 5 | M10: 0 | N10: 5.8
A11: ="P"&TEXT(ROW()-1,"000") -> P010 | B11: Aditya Solanki | C11: Batsman | D11: 11 | E11: 360 | F11: 270 | G11: 0 | H11: 3 | I11: 1 | J11: 1 | K11: 15 | L11: 7 | M11: 0 | N11: 8.7
A12: ="P"&TEXT(ROW()-1,"000") -> P011 | B12: Harshil Mehta | C12: Batsman | D12: 9 | E12: 250 | F12: 182 | G12: 0 | H12: 2 | I12: 0 | J12: 0 | K12: 0 | L12: 3 | M12: 0 | N12: 4.8
A13: ="P"&TEXT(ROW()-1,"000") -> P012 | B13: Pranav Wagh | C13: Batsman | D13: 13 | E13: 495 | F13: 368 | G13: 1 | H13: 4 | I13: 2 | J13: 3 | K13: 28 | L13: 9 | M13: 0 | N13: 13.9
... A61: ="P"&TEXT(ROW()-1,"000") -> P060 | B61: Pratham Goyal | C61: Wicketkeeper | D61: 10 | E61: 225 | F61: 170 | G61: 0 | H61: 1 | I61: 0 | J61: 0 | K61: 0 | L61: 9 | M61: 3 | N61: 6.5

Sheet player_metrics
A1: Player_ID | B1: Player_Name | C1: Role | D1: Matches | E1: Runs | F1: Balls_Faced | G1: Wickets | H1: Overs_Bowled | I1: Runs_Conceded | J1: Strike_Rate | K1: Batting_Average | L1: Economy_Rate | M1: Bowling_Average | N1: impact score | O1: value_index
A2: =raw_data!A24 -> P023 | B2: =raw_data!B24 -> Neel Verma | C2: =raw_data!C24 -> Bowler | D2: =raw_data!D24 -> 8 | E2: =raw_data!E24 -> 25 | F2: =raw_data!F24 -> 20 | G2: =raw_data!I24 -> 9 | H2: =raw_data!J24 -> 25 | I2: =raw_data!K24 -> 220 | J2: =IF(F2=0,"",(E2/F2)*100) -> 125 | K2: =IF(D2=0,"",E2/D2) -> 3.125 | L2: =IF(H2=0,"",I2/H2) -> 8.8 | M2: =IF(G2=0,"",I2/G2) -> 24.444444 | N2: =IF(C2="Batsman", (J2/$J$62*0.6)+(K2/$K$62*0.4), IF(C2="Wicketkeeper", (J2/$J$62*0.55)+(K2/$K$62*0.45), IF(C2="Bowler", (($L$62/L2)*0.55)+(($M$62/M2)*0.45), (J2/$J$62*0.35)+(K2/$K$62*0.25)+(($L$62/L2)*0.2)+(($M$62/M2)*0.2) ))) -> 8.8432792 | O2: =N2/raw_data!N24 -> 1.9651731
A3: =raw_data!A28 -> P027 | B3: =raw_data!B28 -> Hemant Luniya | C3: =raw_data!C28 -> Bowler | D3: =raw_data!D28 -> 9 | E3: =raw_data!E28 -> 35 | F3: =raw_data!F28 -> 25 | G3: =raw_data!I28 -> 11 | H3: =raw_data!J28 -> 28 | I3: =raw_data!K28 -> 240 | J3: =IF(F3=0,"",(E3/F3)*100) -> 140 | K3: =IF(D3=0,"",E3/D3) -> 3.8888889 | L3: =IF(H3=0,"",I3/H3) -> 8.5714286 | M3: =IF(G3=0,"",I3/G3) -> 21.818182 | N3: =IF(C3="Batsman", (J3/$J$62*0.6)+(K3/$K$62*0.4), IF(C3="Wicketkeeper", (J3/$J$62*0.55)+(K3/$K$62*0.45), IF(C3="Bowler", (($L$62/L3)*0.55)+(($M$62/M3)*0.45), (J3/$J$62*0.35)+(K3/$K$62*0.25)+(($L$62/L3)*0.2)+(($M$62/M3)*0.2) ))) -> 9.1178811 | O3: =N3/raw_data!N28 -> 1.5720485
A4: =raw_data!A21 -> P020 | B4: =raw_data!B21 -> Varun Jaitley | C4: =raw_data!C21 -> Bowler | D4: =raw_data!D21 -> 9 | E4: =raw_data!E21 -> 40 | F4: =raw_data!F21 -> 28 | G4: =raw_data!I21 -> 10 | H4: =raw_data!J21 -> 30 | I4: =raw_data!K21 -> 250 | J4: =IF(F4=0,"",(E4/F4)*100) -> 142.85714 | K4: =IF(D4=0,"",E4/D4) -> 4.4444444 | L4: =IF(H4=0,"",I4/H4) -> 8.3333333 | M4: =IF(G4=0,"",I4/G4) -> 25 | N4: =IF(C4="Batsman", (J4/$J$62*0.6)+(K4/$K$62*0.4), IF(C4="Wicketkeeper", (J4/$J$62*0.55)+(K4/$K$62*0.45), IF(C4="Bowler", (($L$62/L4)*0.55)+(($M$62/M4)*0.45), (J4/$J$62*0.35)+(K4/$K$62*0.25)+(($L$62/L4)*0.2)+(($M$62/M4)*0.2) ))) -> 9.306129 | O4: =N4/raw_data!N21 -> 1.5009885
A5: =raw_data!A30 -> P029 | B5: =raw_data!B30 -> Yuvraj Mahadik | C5: =raw_data!C30 -> Bowler | D5: =raw_data!D30 -> 10 | E5: =raw_data!E30 -> 50 | F5: =raw_data!F30 -> 35 | G5: =raw_data!I30 -> 12 | H5: =raw_data!J30 -> 33 | I5: =raw_data!K30 -> 275 | J5: =IF(F5=0,"",(E5/F5)*100) -> 142.85714 | K5: =IF(D5=0,"",E5/D5) -> 5 | L5: =IF(H5=0,"",I5/H5) -> 8.3333333 | M5: =IF(G5=0,"",I5/G5) -> 22.916667 | N5: =IF(C5="Batsman", (J5/$J$62*0.6)+(K5/$K$62*0.4), IF(C5="Wicketkeeper", (J5/$J$62*0.55)+(K5/$K$62*0.45), IF(C5="Bowler", (($L$62/L5)*0.55)+(($M$62/M5)*0.45), (J5/$J$62*0.35)+(K5/$K$62*0.25)+(($L$62/L5)*0.2)+(($M$62/M5)*0.2) ))) -> 9.3429174 | O5: =N5/raw_data!N30 -> 1.3159039
A6: =raw_data!A25 -> P024 | B6: =raw_data!B25 -> Saurabh Pathak | C6: =raw_data!C25 -> Bowler | D6: =raw_data!D25 -> 10 | E6: =raw_data!E25 -> 55 | F6: =raw_data!F25 -> 38 | G6: =raw_data!I25 -> 13 | H6: =raw_data!J25 -> 34 | I6: =raw_data!K25 -> 290 | J6: =IF(F6=0,"",(E6/F6)*100) -> 144.73684 | K6: =IF(D6=0,"",E6/D6) -> 5.5 | L6: =IF(H6=0,"",I6/H6) -> 8.5294118 | M6: =IF(G6=0,"",I6/G6) -> 22.307692 | N6: =IF(C6="Batsman", (J6/$J$62*0.6)+(K6/$K$62*0.4), IF(C6="Wicketkeeper", (J6/$J$62*0.55)+(K6/$K$62*0.45), IF(C6="Bowler", (($L$62/L6)*0.55)+(($M$62/M6)*0.45), (J6/$J$62*0.35)+(K6/$K$62*0.25)+(($L$62/L6)*0.2)+(($M$62/M6)*0.2) ))) -> 9.1503376 | O6: =N6/raw_data!N25 -> 1.2708802
A7: =raw_data!A19 -> P018 | B7: =raw_data!B19 -> Mohit Deshpande | C7: =raw_data!C19 -> Bowler | D7: =raw_data!D19 -> 10 | E7: =raw_data!E19 -> 45 | F7: =raw_data!F19 -> 30 | G7: =raw_data!I19 -> 12 | H7: =raw_data!J19 -> 36 | I7: =raw_data!K19 -> 300 | J7: =IF(F7=0,"",(E7/F7)*100) -> 150 | K7: =IF(D7=0,"",E7/D7) -> 4.5 | L7: =IF(H7=0,"",I7/H7) -> 8.3333333 | M7: =IF(G7=0,"",I7/G7) -> 25 | N7: =IF(C7="Batsman", (J7/$J$62*0.6)+(K7/$K$62*0.4), IF(C7="Wicketkeeper", (J7/$J$62*0.55)+(K7/$K$62*0.45), IF(C7="Bowler", (($L$62/L7)*0.55)+(($M$62/M7)*0.45), (J7/$J$62*0.35)+(K7/$K$62*0.25)+(($L$62/L7)*0.2)+(($M$62/M7)*0.2) ))) -> 9.306129 | O7: =N7/raw_data!N19 -> 1.2408172
A8: =raw_data!A31 -> P030 | B8: =raw_data!B31 -> Tarun Sethi | C8: =raw_data!C31 -> Bowler | D8: =raw_data!D31 -> 11 | E8: =raw_data!E31 -> 65 | F8: =raw_data!F31 -> 48 | G8: =raw_data!I31 -> 14 | H8: =raw_data!J31 -> 39 | I8: =raw_data!K31 -> 315 | J8: =IF(F8=0,"",(E8/F8)*100) -> 135.41667 | K8: =IF(D8=0,"",E8/D8) -> 5.9090909 | L8: =IF(H8=0,"",I8/H8) -> 8.0769231 | M8: =IF(G8=0,"",I8/G8) -> 22.5 | N8: =IF(C8="Batsman", (J8/$J$62*0.6)+(K8/$K$62*0.4), IF(C8="Wicketkeeper", (J8/$J$62*0.55)+(K8/$K$62*0.45), IF(C8="Bowler", (($L$62/L8)*0.55)+(($M$62/M8)*0.45), (J8/$J$62*0.35)+(K8/$K$62*0.25)+(($L$62/L8)*0.2)+(($M$62/M8)*0.2) ))) -> 9.6336785 | O8: =N8/raw_data!N31 -> 1.1468665
A9: =raw_data!A23 -> P022 | B9: =raw_data!B23 -> Rahul Divate | C9: =raw_data!C23 -> Bowler | D9: =raw_data!D23 -> 12 | E9: =raw_data!E23 -> 60 | F9: =raw_data!F23 -> 45 | G9: =raw_data!I23 -> 14 | H9: =raw_data!J23 -> 40 | I9: =raw_data!K23 -> 330 | J9: =IF(F9=0,"",(E9/F9)*100) -> 133.33333 | K9: =IF(D9=0,"",E9/D9) -> 5 | L9: =IF(H9=0,"",I9/H9) -> 8.25 | M9: =IF(G9=0,"",I9/G9) -> 23.571429 | N9: =IF(C9="Batsman", (J9/$J$62*0.6)+(K9/$K$62*0.4), IF(C9="Wicketkeeper", (J9/$J$62*0.55)+(K9/$K$62*0.45), IF(C9="Bowler", (($L$62/L9)*0.55)+(($M$62/M9)*0.45), (J9/$J$62*0.35)+(K9/$K$62*0.25)+(($L$62/L9)*0.2)+(($M$62/M9)*0.2) ))) -> 9.4205683 | O9: =N9/raw_data!N23 -> 1.0584908
A10: =raw_data!A18 -> P017 | B10: =raw_data!B18 -> Siddharth Kaulkar | C10: =raw_data!C18 -> Bowler | D10: =raw_data!D18 -> 11 | E10: =raw_data!E18 -> 70 | F10: =raw_data!F18 -> 50 | G10: =raw_data!I18 -> 15 | H10: =raw_data!J18 -> 42 | I10: =raw_data!K18 -> 340 | J10: =IF(F10=0,"",(E10/F10)*100) -> 140 | K10: =IF(D10=0,"",E10/D10) -> 6.3636364 | L10: =IF(H10=0,"",I10/H10) -> 8.0952381 | M10: =IF(G10=0,"",I10/G10) -> 22.666667 | N10: =IF(C10="Batsman", (J10/$J$62*0.6)+(K10/$K$62*0.4), IF(C10="Wicketkeeper", (J10/$J$62*0.55)+(K10/$K$62*0.45), IF(C10="Bowler", (($L$62/L10)*0.55)+(($M$62/M10)*0.45), (J10/$J$62*0.35)+(K10/$K$62*0.25)+(($L$62/L10)*0.2)+(($M$62/M10)*0.2) ))) -> 9.609594 | O10: =N10/raw_data!N18 -> 0.99067979
A11: =raw_data!A26 -> P025 | B11: =raw_data!B26 -> Gagan Trivedi | C11: =raw_data!C26 -> Bowler | D11: =raw_data!D26 -> 11 | E11: =raw_data!E26 -> 75 | F11: =raw_data!F26 -> 55 | G11: =raw_data!I26 -> 16 | H11: =raw_data!J26 -> 45 | I11: =raw_data!K26 -> 360 | J11: =IF(F11=0,"",(E11/F11)*100) -> 136.36364 | K11: =IF(D11=0,"",E11/D11) -> 6.8181818 | L11: =IF(H11=0,"",I11/H11) -> 8 | M11: =IF(G11=0,"",I11/G11) -> 22.5 | N11: =IF(C11="Batsman", (J11/$J$62*0.6)+(K11/$K$62*0.4), IF(C11="Wicketkeeper", (J11/$J$62*0.55)+(K11/$K$62*0.45), IF(C11="Bowler", (($L$62/L11)*0.55)+(($M$62/M11)*0.45), (J11/$J$62*0.35)+(K11/$K$62*0.25)+(($L$62/L11)*0.2)+(($M$62/M11)*0.2) ))) -> 9.7219866 | O11: =N11/raw_data!N26 -> 0.91716855
A12: =raw_data!A29 -> P028 | B12: =raw_data!B29 -> Keshav Rawat | C12: =raw_data!C29 -> Bowler | D12: =raw_data!D29 -> 12 | E12: =raw_data!E29 -> 90 | F12: =raw_data!F29 -> 65 | G12: =raw_data!I29 -> 17 | H12: =raw_data!J29 -> 44 | I12: =raw_data!K29 -> 350 | J12: =IF(F12=0,"",(E12/F12)*100) -> 138.46154 | K12: =IF(D12=0,"",E12/D12) -> 7.5 | L12: =IF(H12=0,"",I12/H12) -> 7.9545455 | M12: =IF(G12=0,"",I12/G12) -> 20.588235 | N12: =IF(C12="Batsman", (J12/$J$62*0.6)+(K12/$K$62*0.4), IF(C12="Wicketkeeper", (J12/$J$62*0.55)+(K12/$K$62*0.45), IF(C12="Bowler", (($L$62/L12)*0.55)+(($M$62/M12)*0.45), (J12/$J$62*0.35)+(K12/$K$62*0.25)+(($L$62/L12)*0.2)+(($M$62/M12)*0.2) ))) -> 9.8167234 | O12: =N12/raw_data!N29 -> 0.87649316
A13: =raw_data!A17 -> P016 | B13: =raw_data!B17 -> Arjun Bhalerao | C13: =raw_data!C17 -> Bowler | D13: =raw_data!D17 -> 12 | E13: =raw_data!E17 -> 85 | F13: =raw_data!F17 -> 60 | G13: =raw_data!I17 -> 18 | H13: =raw_data!J17 -> 48 | I13: =raw_data!K17 -> 390 | J13: =IF(F13=0,"",(E13/F13)*100) -> 141.66667 | K13: =IF(D13=0,"",E13/D13) -> 7.0833333 | L13: =IF(H13=0,"",I13/H13) -> 8.125 | M13: =IF(G13=0,"",I13/G13) -> 21.666667 | N13: =IF(C13="Batsman", (J13/$J$62*0.6)+(K13/$K$62*0.4), IF(C13="Wicketkeeper", (J13/$J$62*0.55)+(K13/$K$62*0.45), IF(C13="Bowler", (($L$62/L13)*0.55)+(($M$62/M13)*0.45), (J13/$J$62*0.35)+(K13/$K$62*0.25)+(($L$62/L13)*0.2)+(($M$62/M13)*0.2) ))) -> 9.5966288 | O13: =N13/raw_data!N17 -> 0.81327363
A14: =raw_data!A39 -> P038 | B14: =raw_data!B39 -> Arpit Bansal | C14: =raw_data!C39 -> All-Rounder | D14: =raw_data!D39 -> 8 | E14: =raw_data!E39 -> 160 | F14: =raw_data!F39 -> 125 | G14: =raw_data!I39 -> 6 | H14: =raw_data!J39 -> 18 | I14: =raw_data!K39 -> 160 | J14: =IF(F14=0,"",(E14/F14)*100) -> 128 | K14: =IF(D14=0,"",E14/D14) -> 20 | L14: =IF(H14=0,"",I14/H14) -> 8.8888889 | M14: =IF(G14=0,"",I14/G14) -> 26.666667 | N14: =IF(C14="Batsman", (J14/$J$62*0.6)+(K14/$K$62*0.4), IF(C14="Wicketkeeper", (J14/$J$62*0.55)+(K14/$K$62*0.45), IF(C14="Bowler", (($L$62/L14)*0.55)+(($M$62/M14)*0.45), (J14/$J$62*0.35)+(K14/$K$62*0.25)+(($L$62/L14)*0.2)+(($M$62/M14)*0.2) ))) -> 3.7551441 | O14: =N14/raw_data!N39 -> 0.7221431
A15: =raw_data!A27 -> P026 | B15: =raw_data!B27 -> Ritwik Sahaal | C15: =raw_data!C27 -> Bowler | D15: =raw_data!D27 -> 13 | E15: =raw_data!E27 -> 100 | F15: =raw_data!F27 -> 78 | G15: =raw_data!I27 -> 19 | H15: =raw_data!J27 -> 48 | I15: =raw_data!K27 -> 410 | J15: =IF(F15=0,"",(E15/F15)*100) -> 128.20513 | K15: =IF(D15=0,"",E15/D15) -> 7.6923077 | L15: =IF(H15=0,"",I15/H15) -> 8.5416667 | M15: =IF(G15=0,"",I15/G15) -> 21.578947 | N15: =IF(C15="Batsman", (J15/$J$62*0.6)+(K15/$K$62*0.4), IF(C15="Wicketkeeper", (J15/$J$62*0.55)+(K15/$K$62*0.45), IF(C15="Bowler", (($L$62/L15)*0.55)+(($M$62/M15)*0.45), (J15/$J$62*0.35)+(K15/$K$62*0.25)+(($L$62/L15)*0.2)+(($M$62/M15)*0.2) ))) -> 9.1531757 | O15: =N15/raw_data!N27 -> 0.68307281
A16: =raw_data!A20 -> P019 | B16: =raw_data!B20 -> Laksh Nayak | C16: =raw_data!C20 -> Bowler | D16: =raw_data!D20 -> 13 | E16: =raw_data!E20 -> 110 | F16: =raw_data!F20 -> 75 | G16: =raw_data!I20 -> 20 | H16: =raw_data!J20 -> 52 | I16: =raw_data!K20 -> 430 | J16: =IF(F16=0,"",(E16/F16)*100) -> 146.66667 | K16: =IF(D16=0,"",E16/D16) -> 8.4615385 | L16: =IF(H16=0,"",I16/H16) -> 8.2692308 | M16: =IF(G16=0,"",I16/G16) -> 21.5 | N16: =IF(C16="Batsman", (J16/$J$62*0.6)+(K16/$K$62*0.4), IF(C16="Wicketkeeper", (J16/$J$62*0.55)+(K16/$K$62*0.45), IF(C16="Bowler", (($L$62/L16)*0.55)+(($M$62/M16)*0.45), (J16/$J$62*0.35)+(K16/$K$62*0.25)+(($L$62/L16)*0.2)+(($M$62/M16)*0.2) ))) -> 9.4410095 | O16: =N16/raw_data!N20 -> 0.66485982
A17: =raw_data!A22 -> P021 | B17: =raw_data!B22 -> Parth Keni | C17: =raw_data!C22 -> Bowler | D17: =raw_data!D22 -> 14 | E17: =raw_data!E22 -> 95 | F17: =raw_data!F22 -> 70 | G17: =raw_data!I22 -> 22 | H17: =raw_data!J22 -> 50 | I17: =raw_data!K22 -> 420 | J17: =IF(F17=0,"",(E17/F17)*100) -> 135.71429 | K17: =IF(D17=0,"",E17/D17) -> 6.7857143 | L17: =IF(H17=0,"",I17/H17) -> 8.4 | M17: =IF(G17=0,"",I17/G17) -> 19.090909 | N17: =IF(C17="Batsman", (J17/$J$62*0.6)+(K17/$K$62*0.4), IF(C17="Wicketkeeper", (J17/$J$62*0.55)+(K17/$K$62*0.45), IF(C17="Bowler", (($L$62/L17)*0.55)+(($M$62/M17)*0.45), (J17/$J$62*0.35)+(K17/$K$62*0.25)+(($L$62/L17)*0.2)+(($M$62/M17)*0.2) ))) -> 9.3607384 | O17: =N17/raw_data!N22 -> 0.6039186
A18: =raw_data!A36 -> P035 | B18: =raw_data!B36 -> Soham Borkar | C18: =raw_data!C36 -> All-Rounder | D18: =raw_data!D36 -> 9 | E18: =raw_data!E36 -> 180 | F18: =raw_data!F36 -> 130 | G18: =raw_data!I36 -> 7 | H18: =raw_data!J36 -> 20 | I18: =raw_data!K36 -> 190 | J18: =IF(F18=0,"",(E18/F18)*100) -> 138.46154 | K18: =IF(D18=0,"",E18/D18) -> 20 | L18: =IF(H18=0,"",I18/H18) -> 9.5 | M18: =IF(G18=0,"",I18/G18) -> 27.142857 | N18: =IF(C18="Batsman", (J18/$J$62*0.6)+(K18/$K$62*0.4), IF(C18="Wicketkeeper", (J18/$J$62*0.55)+(K18/$K$62*0.45), IF(C18="Bowler", (($L$62/L18)*0.55)+(($M$62/M18)*0.45), (J18/$J$62*0.35)+(K18/$K$62*0.25)+(($L$62/L18)*0.2)+(($M$62/M18)*0.2) ))) -> 3.5841271 | O18: =N18/raw_data!N36 -> 0.56890907
A19: =raw_data!A44 -> P043 | B19: =raw_data!B44 -> Prerit Anand | C19: =raw_data!C44 -> All-Rounder | D19: =raw_data!D44 -> 9 | E19: =raw_data!E44 -> 190 | F19: =raw_data!F44 -> 150 | G19: =raw_data!I44 -> 7 | H19: =raw_data!J44 -> 22 | I19: =raw_data!K44 -> 200 | J19: =IF(F19=0,"",(E19/F19)*100) -> 126.66667 | K19: =IF(D19=0,"",E19/D19) -> 21.111111 | L19: =IF(H19=0,"",I19/H19) -> 9.0909091 | M19: =IF(G19=0,"",I19/G19) -> 28.571429 | N19: =IF(C19="Batsman", (J19/$J$62*0.6)+(K19/$K$62*0.4), IF(C19="Wicketkeeper", (J19/$J$62*0.55)+(K19/$K$62*0.45), IF(C19="Bowler", (($L$62/L19)*0.55)+(($M$62/M19)*0.45), (J19/$J$62*0.35)+(K19/$K$62*0.25)+(($L$62/L19)*0.2)+(($M$62/M19)*0.2) ))) -> 3.6852174 | O19: =N19/raw_data!N44 -> 0.54194374
A20: =raw_data!A34 -> P033 | B20: =raw_data!B34 -> Dhruv Menon | C20: =raw_data!C34 -> All-Rounder | D20: =raw_data!D34 -> 10 | E20: =raw_data!E34 -> 210 | F20: =raw_data!F34 -> 160 | G20: =raw_data!I34 -> 8 | H20: =raw_data!J34 -> 24 | I20: =raw_data!K34 -> 210 | J20: =IF(F20=0,"",(E20/F20)*100) -> 131.25 | K20: =IF(D20=0,"",E20/D20) -> 21 | L20: =IF(H20=0,"",I20/H20) -> 8.75 | M20: =IF(G20=0,"",I20/G20) -> 26.25 | N20: =IF(C20="Batsman", (J20/$J$62*0.6)+(K20/$K$62*0.4), IF(C20="Wicketkeeper", (J20/$J$62*0.55)+(K20/$K$62*0.45), IF(C20="Bowler", (($L$62/L20)*0.55)+(($M$62/M20)*0.45), (J20/$J$62*0.35)+(K20/$K$62*0.25)+(($L$62/L20)*0.2)+(($M$62/M20)*0.2) ))) -> 3.8254112 | O20: =N20/raw_data!N34 -> 0.47227299
A21: =raw_data!A41 -> P040 | B21: =raw_data!B41 -> Manav Reddy | C21: =raw_data!C41 -> All-Rounder | D21: =raw_data!D41 -> 10 | E21: =raw_data!E41 -> 220 | F21: =raw_data!F41 -> 170 | G21: =raw_data!I41 -> 9 | H21: =raw_data!J41 -> 26 | I21: =raw_data!K41 -> 230 | J21: =IF(F21=0,"",(E21/F21)*100) -> 129.41176 | K21: =IF(D21=0,"",E21/D21) -> 22 | L21: =IF(H21=0,"",I21/H21) -> 8.8461538 | M21: =IF(G21=0,"",I21/G21) -> 25.555556 | N21: =IF(C21="Batsman", (J21/$J$62*0.6)+(K21/$K$62*0.4), IF(C21="Wicketkeeper", (J21/$J$62*0.55)+(K21/$K$62*0.45), IF(C21="Bowler", (($L$62/L21)*0.55)+(($M$62/M21)*0.45), (J21/$J$62*0.35)+(K21/$K$62*0.25)+(($L$62/L21)*0.2)+(($M$62/M21)*0.2) ))) -> 3.8027759 | O21: =N21/raw_data!N41 -> 0.41788746
A22: =raw_data!A46 -> P045 | B22: =raw_data!B46 -> Yatin Choudhary | C22: =raw_data!C46 -> All-Rounder | D22: =raw_data!D46 -> 10 | E22: =raw_data!E46 -> 240 | F22: =raw_data!F46 -> 185 | G22: =raw_data!I46 -> 9 | H22: =raw_data!J46 -> 25 | I22: =raw_data!K46 -> 220 | J22: =IF(F22=0,"",(E22/F22)*100) -> 129.72973 | K22: =IF(D22=0,"",E22/D22) -> 24 | L22: =IF(H22=0,"",I22/H22) -> 8.8 | M22: =IF(G22=0,"",I22/G22) -> 24.444444 | N22: =IF(C22="Batsman", (J22/$J$62*0.6)+(K22/$K$62*0.4), IF(C22="Wicketkeeper", (J22/$J$62*0.55)+(K22/$K$62*0.45), IF(C22="Bowler", (($L$62/L22)*0.55)+(($M$62/M22)*0.45), (J22/$J$62*0.35)+(K22/$K$62*0.25)+(($L$62/L22)*0.2)+(($M$62/M22)*0.2) ))) -> 3.8495684 | O22: =N22/raw_data!N46 -> 0.41393208
A23: =raw_data!A33 -> P032 | B23: =raw_data!B33 -> Amitesh Pillai | C23: =raw_data!C33 -> All-Rounder | D23: =raw_data!D33 -> 11 | E23: =raw_data!E33 -> 260 | F23: =raw_data!F33 -> 200 | G23: =raw_data!I33 -> 10 | H23: =raw_data!J33 -> 28 | I23: =raw_data!K33 -> 250 | J23: =IF(F23=0,"",(E23/F23)*100) -> 130 | K23: =IF(D23=0,"",E23/D23) -> 23.636364 | L23: =IF(H23=0,"",I23/H23) -> 8.9285714 | M23: =IF(G23=0,"",I23/G23) -> 25 | N23: =IF(C23="Batsman", (J23/$J$62*0.6)+(K23/$K$62*0.4), IF(C23="Wicketkeeper", (J23/$J$62*0.55)+(K23/$K$62*0.45), IF(C23="Bowler", (($L$62/L23)*0.55)+(($M$62/M23)*0.45), (J23/$J$62*0.35)+(K23/$K$62*0.25)+(($L$62/L23)*0.2)+(($M$62/M23)*0.2) ))) -> 3.7980468 | O23: =N23/raw_data!N33 -> 0.36519681
A24: =raw_data!A45 -> P044 | B24: =raw_data!B45 -> Samarjeet Gill | C24: =raw_data!C45 -> All-Rounder | D24: =raw_data!D45 -> 11 | E24: =raw_data!E45 -> 280 | F24: =raw_data!F45 -> 215 | G24: =raw_data!I45 -> 10 | H24: =raw_data!J45 -> 28 | I24: =raw_data!K45 -> 255 | J24: =IF(F24=0,"",(E24/F24)*100) -> 130.23256 | K24: =IF(D24=0,"",E24/D24) -> 25.454545 | L24: =IF(H24=0,"",I24/H24) -> 9.1071429 | M24: =IF(G24=0,"",I24/G24) -> 25.5 | N24: =IF(C24="Batsman", (J24/$J$62*0.6)+(K24/$K$62*0.4), IF(C24="Wicketkeeper", (J24/$J$62*0.55)+(K24/$K$62*0.45), IF(C24="Bowler", (($L$62/L24)*0.55)+(($M$62/M24)*0.45), (J24/$J$62*0.35)+(K24/$K$62*0.25)+(($L$62/L24)*0.2)+(($M$62/M24)*0.2) ))) -> 3.7558658 | O24: =N24/raw_data!N45 -> 0.34457485
A25: =raw_data!A38 -> P037 | B25: =raw_data!B38 -> Nirav Doshi | C25: =raw_data!C38 -> All-Rounder | D25: =raw_data!D38 -> 12 | E25: =raw_data!E38 -> 275 | F25: =raw_data!F38 -> 205 | G25: =raw_data!I38 -> 11 | H25: =raw_data!J38 -> 30 | I25: =raw_data!K38 -> 270 | J25: =IF(F25=0,"",(E25/F25)*100) -> 134.14634 | K25: =IF(D25=0,"",E25/D25) -> 22.916667 | L25: =IF(H25=0,"",I25/H25) -> 9 | M25: =IF(G25=0,"",I25/G25) -> 24.545455 | N25: =IF(C25="Batsman", (J25/$J$62*0.6)+(K25/$K$62*0.4), IF(C25="Wicketkeeper", (J25/$J$62*0.55)+(K25/$K$62*0.45), IF(C25="Bowler", (($L$62/L25)*0.55)+(($M$62/M25)*0.45), (J25/$J$62*0.35)+(K25/$K$62*0.25)+(($L$62/L25)*0.2)+(($M$62/M25)*0.2) ))) -> 3.7802521 | O25: =N25/raw_data!N38 -> 0.32871757
A26: =raw_data!A42 -> P041 | B26: =raw_data!B42 -> Harit Shah | C26: =raw_data!C42 -> All-Rounder | D26: =raw_data!D42 -> 12 | E26: =raw_data!E42 -> 310 | F26: =raw_data!F42 -> 240 | G26: =raw_data!I42 -> 12 | H26: =raw_data!J42 -> 32 | I26: =raw_data!K42 -> 285 | J26: =IF(F26=0,"",(E26/F26)*100) -> 129.16667 | K26: =IF(D26=0,"",E26/D26) -> 25.833333 | L26: =IF(H26=0,"",I26/H26) -> 8.90625 | M26: =IF(G26=0,"",I26/G26) -> 23.75 | N26: =IF(C26="Batsman", (J26/$J$62*0.6)+(K26/$K$62*0.4), IF(C26="Wicketkeeper", (J26/$J$62*0.55)+(K26/$K$62*0.45), IF(C26="Bowler", (($L$62/L26)*0.55)+(($M$62/M26)*0.45), (J26/$J$62*0.35)+(K26/$K$62*0.25)+(($L$62/L26)*0.2)+(($M$62/M26)*0.2) ))) -> 3.8370637 | O26: =N26/raw_data!N42 -> 0.30944062
A27: =raw_data!A32 -> P031 | B27: =raw_data!B32 -> Rohan Mankad | C27: =raw_data!C32 -> All-Rounder | D27: =raw_data!D32 -> 12 | E27: =raw_data!E32 -> 320 | F27: =raw_data!F32 -> 240 | G27: =raw_data!I32 -> 12 | H27: =raw_data!J32 -> 32 | I27: =raw_data!K32 -> 290 | J27: =IF(F27=0,"",(E27/F27)*100) -> 133.33333 | K27: =IF(D27=0,"",E27/D27) -> 26.666667 | L27: =IF(H27=0,"",I27/H27) -> 9.0625 | M27: =IF(G27=0,"",I27/G27) -> 24.166667 | N27: =IF(C27="Batsman", (J27/$J$62*0.6)+(K27/$K$62*0.4), IF(C27="Wicketkeeper", (J27/$J$62*0.55)+(K27/$K$62*0.45), IF(C27="Bowler", (($L$62/L27)*0.55)+(($M$62/M27)*0.45), (J27/$J$62*0.35)+(K27/$K$62*0.25)+(($L$62/L27)*0.2)+(($M$62/M27)*0.2) ))) -> 3.8015511 | O27: =N27/raw_data!N32 -> 0.29469388
A28: =raw_data!A40 -> P039 | B28: =raw_data!B40 -> Siddhant Gokhale | C28: =raw_data!C40 -> All-Rounder | D28: =raw_data!D40 -> 11 | E28: =raw_data!E40 -> 300 | F28: =raw_data!F40 -> 230 | G28: =raw_data!I40 -> 13 | H28: =raw_data!J40 -> 34 | I28: =raw_data!K40 -> 295 | J28: =IF(F28=0,"",(E28/F28)*100) -> 130.43478 | K28: =IF(D28=0,"",E28/D28) -> 27.272727 | L28: =IF(H28=0,"",I28/H28) -> 8.6764706 | M28: =IF(G28=0,"",I28/G28) -> 22.692308 | N28: =IF(C28="Batsman", (J28/$J$62*0.6)+(K28/$K$62*0.4), IF(C28="Wicketkeeper", (J28/$J$62*0.55)+(K28/$K$62*0.45), IF(C28="Bowler", (($L$62/L28)*0.55)+(($M$62/M28)*0.45), (J28/$J$62*0.35)+(K28/$K$62*0.25)+(($L$62/L28)*0.2)+(($M$62/M28)*0.2) ))) -> 3.9452042 | O28: =N28/raw_data!N40 -> 0.29008855
A29: =raw_data!A43 -> P042 | B29: =raw_data!B43 -> Vikram Khurana | C29: =raw_data!C43 -> All-Rounder | D29: =raw_data!D43 -> 13 | E29: =raw_data!E43 -> 330 | F29: =raw_data!F43 -> 250 | G29: =raw_data!I43 -> 14 | H29: =raw_data!J43 -> 35 | I29: =raw_data!K43 -> 305 | J29: =IF(F29=0,"",(E29/F29)*100) -> 132 | K29: =IF(D29=0,"",E29/D29) -> 25.384615 | L29: =IF(H29=0,"",I29/H29) -> 8.7142857 | M29: =IF(G29=0,"",I29/G29) -> 21.785714 | N29: =IF(C29="Batsman", (J29/$J$62*0.6)+(K29/$K$62*0.4), IF(C29="Wicketkeeper", (J29/$J$62*0.55)+(K29/$K$62*0.45), IF(C29="Bowler", (($L$62/L29)*0.55)+(($M$62/M29)*0.45), (J29/$J$62*0.35)+(K29/$K$62*0.25)+(($L$62/L29)*0.2)+(($M$62/M29)*0.2) ))) -> 3.9232732 | O29: =N29/raw_data!N43 -> 0.26330692
A30: =raw_data!A35 -> P034 | B30: =raw_data!B35 -> Kartik Iyer | C30: =raw_data!C35 -> All-Rounder | D30: =raw_data!D35 -> 13 | E30: =raw_data!E35 -> 340 | F30: =raw_data!F35 -> 255 | G30: =raw_data!I35 -> 14 | H30: =raw_data!J35 -> 36 | I30: =raw_data!K35 -> 310 | J30: =IF(F30=0,"",(E30/F30)*100) -> 133.33333 | K30: =IF(D30=0,"",E30/D30) -> 26.153846 | L30: =IF(H30=0,"",I30/H30) -> 8.6111111 | M30: =IF(G30=0,"",I30/G30) -> 22.142857 | N30: =IF(C30="Batsman", (J30/$J$62*0.6)+(K30/$K$62*0.4), IF(C30="Wicketkeeper", (J30/$J$62*0.55)+(K30/$K$62*0.45), IF(C30="Bowler", (($L$62/L30)*0.55)+(($M$62/M30)*0.45), (J30/$J$62*0.35)+(K30/$K$62*0.25)+(($L$62/L30)*0.2)+(($M$62/M30)*0.2) ))) -> 3.9689448 | O30: =N30/raw_data!N35 -> 0.26111479
A31: =raw_data!A54 -> P053 | B31: =raw_data!B54 -> Harsh Daga | C31: =raw_data!C54 -> Wicketkeeper | D31: =raw_data!D54 -> 8 | E31: =raw_data!E54 -> 190 | F31: =raw_data!F54 -> 140 | G31: =raw_data!I54 -> 0 | H31: =raw_data!J54 -> 0 | I31: =raw_data!K54 -> 0 | J31: =IF(F31=0,"",(E31/F31)*100) -> 135.71429 | K31: =IF(D31=0,"",E31/D31) -> 23.75 | L31: =IF(H31=0,"",I31/H31) | M31: =IF(G31=0,"",I31/G31) | N31: =IF(C31="Batsman", (J31/$J$62*0.6)+(K31/$K$62*0.4), IF(C31="Wicketkeeper", (J31/$J$62*0.55)+(K31/$K$62*0.45), IF(C31="Bowler", (($L$62/L31)*0.55)+(($M$62/M31)*0.45), (J31/$J$62*0.35)+(K31/$K$62*0.25)+(($L$62/L31)*0.2)+(($M$62/M31)*0.2) ))) -> 1.023205 | O31: =N31/raw_data!N54 -> 0.23795465
A32: =raw_data!A37 -> P036 | B32: =raw_data!B37 -> Jayant Pande | C32: =raw_data!C37 -> All-Rounder | D32: =raw_data!D37 -> 14 | E32: =raw_data!E37 -> 350 | F32: =raw_data!F37 -> 260 | G32: =raw_data!I37 -> 15 | H32: =raw_data!J37 -> 38 | I32: =raw_data!K37 -> 330 | J32: =IF(F32=0,"",(E32/F32)*100) -> 134.61538 | K32: =IF(D32=0,"",E32/D32) -> 25 | L32: =IF(H32=0,"",I32/H32) -> 8.6842105 | M32: =IF(G32=0,"",I32/G32) -> 22 | N32: =IF(C32="Batsman", (J32/$J$62*0.6)+(K32/$K$62*0.4), IF(C32="Wicketkeeper", (J32/$J$62*0.55)+(K32/$K$62*0.45), IF(C32="Bowler", (($L$62/L32)*0.55)+(($M$62/M32)*0.45), (J32/$J$62*0.35)+(K32/$K$62*0.25)+(($L$62/L32)*0.2)+(($M$62/M32)*0.2) ))) -> 3.9345436 | O32: =N32/raw_data!N37 -> 0.23419902
A33: =raw_data!A12 -> P011 | B33: =raw_data!B12 -> Harshil Mehta | C33: =raw_data!C12 -> Batsman | D33: =raw_data!D12 -> 9 | E33: =raw_data!E12 -> 250 | F33: =raw_data!F12 -> 182 | G33: =raw_data!I12 -> 0 | H33: =raw_data!J12 -> 0 | I33: =raw_data!K12 -> 0 | J33: =IF(F33=0,"",(E33/F33)*100) -> 137.36264 | K33: =IF(D33=0,"",E33/D33) -> 27.777778 | L33: =IF(H33=0,"",I33/H33) | M33: =IF(G33=0,"",I33/G33) | N33: =IF(C33="Batsman", (J33/$J$62*0.6)+(K33/$K$62*0.4), IF(C33="Wicketkeeper", (J33/$J$62*0.55)+(K33/$K$62*0.45), IF(C33="Bowler", (($L$62/L33)*0.55)+(($M$62/M33)*0.45), (J33/$J$62*0.35)+(K33/$K$62*0.25)+(($L$62/L33)*0.2)+(($M$62/M33)*0.2) ))) -> 1.0994705 | O33: =N33/raw_data!N12 -> 0.22905635
A34: =raw_data!A7 -> P006 | B34: =raw_data!B7 -> Manan Kapoor | C34: =raw_data!C7 -> Batsman | D34: =raw_data!D7 -> 8 | E34: =raw_data!E7 -> 265 | F34: =raw_data!F7 -> 185 | G34: =raw_data!I7 -> 0 | H34: =raw_data!J7 -> 0 | I34: =raw_data!K7 -> 0 | J34: =IF(F34=0,"",(E34/F34)*100) -> 143.24324 | K34: =IF(D34=0,"",E34/D34) -> 33.125 | L34: =IF(H34=0,"",I34/H34) | M34: =IF(G34=0,"",I34/G34) | N34: =IF(C34="Batsman", (J34/$J$62*0.6)+(K34/$K$62*0.4), IF(C34="Wicketkeeper", (J34/$J$62*0.55)+(K34/$K$62*0.45), IF(C34="Bowler", (($L$62/L34)*0.55)+(($M$62/M34)*0.45), (J34/$J$62*0.35)+(K34/$K$62*0.25)+(($L$62/L34)*0.2)+(($M$62/M34)*0.2) ))) -> 1.2196455 | O34: =N34/raw_data!N7 -> 0.22175372
A35: =raw_data!A16 -> P015 | B35: =raw_data!B16 -> Vedant Kulkarni | C35: =raw_data!C16 -> Batsman | D35: =raw_data!D16 -> 11 | E35: =raw_data!E16 -> 275 | F35: =raw_data!F16 -> 200 | G35: =raw_data!I16 -> 0 | H35: =raw_data!J16 -> 0 | I35: =raw_data!K16 -> 0 | J35: =IF(F35=0,"",(E35/F35)*100) -> 137.5 | K35: =IF(D35=0,"",E35/D35) -> 25 | L35: =IF(H35=0,"",I35/H35) | M35: =IF(G35=0,"",I35/G35) | N35: =IF(C35="Batsman", (J35/$J$62*0.6)+(K35/$K$62*0.4), IF(C35="Wicketkeeper", (J35/$J$62*0.55)+(K35/$K$62*0.45), IF(C35="Bowler", (($L$62/L35)*0.55)+(($M$62/M35)*0.45), (J35/$J$62*0.35)+(K35/$K$62*0.25)+(($L$62/L35)*0.2)+(($M$62/M35)*0.2) ))) -> 1.0512432 | O35: =N35/raw_data!N16 -> 0.20216215
A36: =raw_data!A5 -> P004 | B36: =raw_data!B5 -> Kunal Purohit | C36: =raw_data!C5 -> Batsman | D36: =raw_data!D5 -> 9 | E36: =raw_data!E5 -> 298 | F36: =raw_data!F5 -> 210 | G36: =raw_data!I5 -> 0 | H36: =raw_data!J5 -> 0 | I36: =raw_data!K5 -> 0 | J36: =IF(F36=0,"",(E36/F36)*100) -> 141.90476 | K36: =IF(D36=0,"",E36/D36) -> 33.111111 | L36: =IF(H36=0,"",I36/H36) | M36: =IF(G36=0,"",I36/G36) | N36: =IF(C36="Batsman", (J36/$J$62*0.6)+(K36/$K$62*0.4), IF(C36="Wicketkeeper", (J36/$J$62*0.55)+(K36/$K$62*0.45), IF(C36="Bowler", (($L$62/L36)*0.55)+(($M$62/M36)*0.45), (J36/$J$62*0.35)+(K36/$K$62*0.25)+(($L$62/L36)*0.2)+(($M$62/M36)*0.2) ))) -> 1.2134468 | O36: =N36/raw_data!N5 -> 0.19571722
A37: =raw_data!A10 -> P009 | B37: =raw_data!B10 -> Samar Khatri | C37: =raw_data!C10 -> Batsman | D37: =raw_data!D10 -> 10 | E37: =raw_data!E10 -> 280 | F37: =raw_data!F10 -> 195 | G37: =raw_data!I10 -> 0 | H37: =raw_data!J10 -> 0 | I37: =raw_data!K10 -> 0 | J37: =IF(F37=0,"",(E37/F37)*100) -> 143.58974 | K37: =IF(D37=0,"",E37/D37) -> 28 | L37: =IF(H37=0,"",I37/H37) | M37: =IF(G37=0,"",I37/G37) | N37: =IF(C37="Batsman", (J37/$J$62*0.6)+(K37/$K$62*0.4), IF(C37="Wicketkeeper", (J37/$J$62*0.55)+(K37/$K$62*0.45), IF(C37="Bowler", (($L$62/L37)*0.55)+(($M$62/M37)*0.45), (J37/$J$62*0.35)+(K37/$K$62*0.25)+(($L$62/L37)*0.2)+(($M$62/M37)*0.2) ))) -> 1.1310801 | O37: =N37/raw_data!N10 -> 0.19501382
A38: =raw_data!A51 -> P050 | B38: =raw_data!B51 -> Rohit Tamhane | C38: =raw_data!C51 -> Wicketkeeper | D38: =raw_data!D51 -> 9 | E38: =raw_data!E51 -> 200 | F38: =raw_data!F51 -> 150 | G38: =raw_data!I51 -> 0 | H38: =raw_data!J51 -> 0 | I38: =raw_data!K51 -> 0 | J38: =IF(F38=0,"",(E38/F38)*100) -> 133.33333 | K38: =IF(D38=0,"",E38/D38) -> 22.222222 | L38: =IF(H38=0,"",I38/H38) | M38: =IF(G38=0,"",I38/G38) | N38: =IF(C38="Batsman", (J38/$J$62*0.6)+(K38/$K$62*0.4), IF(C38="Wicketkeeper", (J38/$J$62*0.55)+(K38/$K$62*0.45), IF(C38="Bowler", (($L$62/L38)*0.55)+(($M$62/M38)*0.45), (J38/$J$62*0.35)+(K38/$K$62*0.25)+(($L$62/L38)*0.2)+(($M$62/M38)*0.2) ))) -> 0.98327676 | O38: =N38/raw_data!N51 -> 0.19279937
A39: =raw_data!A59 -> P058 | B39: =raw_data!B59 -> Keshin Parekh | C39: =raw_data!C59 -> Wicketkeeper | D39: =raw_data!D59 -> 9 | E39: =raw_data!E59 -> 210 | F39: =raw_data!F59 -> 160 | G39: =raw_data!I59 -> 0 | H39: =raw_data!J59 -> 0 | I39: =raw_data!K59 -> 0 | J39: =IF(F39=0,"",(E39/F39)*100) -> 131.25 | K39: =IF(D39=0,"",E39/D39) -> 23.333333 | L39: =IF(H39=0,"",I39/H39) | M39: =IF(G39=0,"",I39/G39) | N39: =IF(C39="Batsman", (J39/$J$62*0.6)+(K39/$K$62*0.4), IF(C39="Wicketkeeper", (J39/$J$62*0.55)+(K39/$K$62*0.45), IF(C39="Bowler", (($L$62/L39)*0.55)+(($M$62/M39)*0.45), (J39/$J$62*0.35)+(K39/$K$62*0.25)+(($L$62/L39)*0.2)+(($M$62/M39)*0.2) ))) -> 0.99675824 | O39: =N39/raw_data!N59 -> 0.18458486
A40: =raw_data!A15 -> P014 | B40: =raw_data!B15 -> Tanish Roy | C40: =raw_data!C15 -> Batsman | D40: =raw_data!D15 -> 10 | E40: =raw_data!E15 -> 310 | F40: =raw_data!F15 -> 225 | G40: =raw_data!I15 -> 0 | H40: =raw_data!J15 -> 0 | I40: =raw_data!K15 -> 0 | J40: =IF(F40=0,"",(E40/F40)*100) -> 137.77778 | K40: =IF(D40=0,"",E40/D40) -> 31 | L40: =IF(H40=0,"",I40/H40) | M40: =IF(G40=0,"",I40/G40) | N40: =IF(C40="Batsman", (J40/$J$62*0.6)+(K40/$K$62*0.4), IF(C40="Wicketkeeper", (J40/$J$62*0.55)+(K40/$K$62*0.45), IF(C40="Bowler", (($L$62/L40)*0.55)+(($M$62/M40)*0.45), (J40/$J$62*0.35)+(K40/$K$62*0.25)+(($L$62/L40)*0.2)+(($M$62/M40)*0.2) ))) -> 1.1579698 | O40: =N40/raw_data!N15 -> 0.17814921
...

Sheet squad_selection
A1: player_name | B1: Role | C1: Auction_price | D1: Impact_score | E1: Value_index | F1: selected
A2: =player_metrics!B54 -> Vivek Shetty | B2: =player_metrics!C54 -> Wicketkeeper | C2: =raw_data!N54 -> 4.3 | D2: =player_metrics!N54 -> 1.0822315 | E2: =player_metrics!O54 -> 0.091714534 | F2: 1 | H2: Total players | I2: =SUM(F2:F61) -> 12
A3: =player_metrics!B24 -> Samarjeet Gill | B3: =player_metrics!C24 -> All-Rounder | C3: =raw_data!N24 -> 4.5 | D3: =player_metrics!N24 -> 3.7558658 | E3: =player_metrics!O24 -> 0.34457485 | F3: 0 | H3: Total Cost | I3: 90
A4: =player_metrics!B12 -> Keshav Rawat | B4: =player_metrics!C12 -> Bowler | C4: =raw_data!N12 -> 4.8 | D4: =player_metrics!N12 -> 9.8167234 | E4: =player_metrics!O12 -> 0.87649316 | F4: 1 | H4: Batsmen | I4: =COUNTIFS(B2:B61,"Batsman",F2:F61,1) -> 4
A5: =player_metrics!B51 -> Dev Malhotra | B5: =player_metrics!C51 -> Batsman | C5: =raw_data!N51 -> 5.1 | D5: =player_metrics!N51 -> 1.3603784 | E5: =player_metrics!O51 -> 0.11150643 | F5: 1 | H5: Bowlers | I5: =COUNTIFS(B2:B61,"Bowler",F2:F61,1) -> 4
A6: =player_metrics!B16 -> Laksh Nayak | B6: =player_metrics!C16 -> Bowler | C6: =raw_data!N16 -> 5.2 | D6: =player_metrics!N16 -> 9.4410095 | E6: =player_metrics!O16 -> 0.66485982 | F6: 1 | H6: All-Rounders | I6: =COUNTIFS(B2:B61,"All-Rounder",F2:F61,1) -> 3
A7: =player_metrics!B39 -> Keshin Parekh | B7: =player_metrics!C39 -> Wicketkeeper | C7: =raw_data!N39 -> 5.2 | D7: =player_metrics!N39 -> 0.99675824 | E7: =player_metrics!O39 -> 0.18458486 | F7: 0 | H7: Wicketkeepers | I7: =COUNTIFS(B2:B61,"Wicketkeeper",F2:F61,1) -> 1
A8: =player_metrics!B59 -> Yash Vartak | B8: =player_metrics!C59 -> Batsman | C8: =raw_data!N59 -> 5.4 | D8: =player_metrics!N59 -> 1.3279097 | E8: =player_metrics!O59 -> 0.076757787 | F8: 1
A9: =player_metrics!B7 -> Mohit Deshpande | B9: =player_metrics!C7 -> Bowler | C9: =raw_data!N7 -> 5.5 | D9: =player_metrics!N7 -> 9.306129 | E9: =player_metrics!O7 -> 1.2408172 | F9: 0
A10: =player_metrics!B10 -> Siddharth Kaulkar | B10: =player_metrics!C10 -> Bowler | C10: =raw_data!N10 -> 5.8 | D10: =player_metrics!N10 -> 9.609594 | E10: =player_metrics!O10 -> 0.99067979 | F10: 0 | H10: Team Impact | I10: =SUMPRODUCT(D2:D61,F2:F61) -> 56.466574
A11: =player_metrics!B28 -> Siddhant Gokhale | B11: =player_metrics!C28 -> All-Rounder | C11: =raw_data!N28 -> 5.8 | D11: =player_metrics!N28 -> 3.9452042 | E11: =player_metrics!O28 -> 0.29008855 | F11: 1
A12: =player_metrics!B5 -> Yuvraj Mahadik | B12: =player_metrics!C5 -> Bowler | C12: =raw_data!N5 -> 6.2 | D12: =player_metrics!N5 -> 9.3429174 | E12: =player_metrics!O5 -> 1.3159039 | F12: 0
A13: =player_metrics!B21 -> Manav Reddy | B13: =player_metrics!C21 -> All-Rounder | C13: =raw_data!N21 -> 6.2 | D13: =player_metrics!N21 -> 3.8027759 | E13: =player_metrics!O21 -> 0.41788746 | F13: 0
A14: =player_metrics!B56 -> Ritesh Walia | B14: =player_metrics!C56 -> Wicketkeeper | C14: =raw_data!N56 -> 6.2 | D14: =player_metrics!N56 -> 1.1729733 | E14: =player_metrics!O56 -> 0.088861612 | F14: 0
A15: =player_metrics!B36 -> Kunal Purohit | B15: =player_metrics!C36 -> Batsman | C15: =raw_data!N36 -> 6.3 | D15: =player_metrics!N36 -> 1.2134468 | E15: =player_metrics!O36 -> 0.19571722 | F15: 0
A16: =player_metrics!B15 -> Ritwik Sahaal | B16: =player_metrics!C15 -> Bowler | C16: =raw_data!N15 -> 6.5 | D16: =player_metrics!N15 -> 9.1531757 | E16: =player_metrics!O15 -> 0.68307281 | F16: 0
A17: =player_metrics!B61 -> Naman Luthra | B17: =player_metrics!C61 -> Wicketkeeper | C17: =raw_data!N61 -> 6.5 | D17: =player_metrics!N61 -> 1.1286219 | E17: =player_metrics!O61 -> 0.064492679 | F17: 0
A18: =player_metrics!B44 -> Aditya Solanki | B18: =player_metrics!C44 -> Batsman | C18: =raw_data!N44 -> 6.8 | D18: =player_metrics!N44 -> 1.1685664 | E18: =player_metrics!O44 -> 0.13431798 | F18: 0
A19: =player_metrics!B30 -> Kartik Iyer | B19: =player_metrics!C30 -> All-Rounder | C19: =raw_data!N30 -> 7.1 | D19: =player_metrics!N30 -> 3.9689448 | E19: =player_metrics!O30 -> 0.26111479 | F19: 0
A20: =player_metrics!B25 -> Nirav Doshi | B20: =player_metrics!C25 -> All-Rounder | C20: =raw_data!N25 -> 7.2 | D20: =player_metrics!N25 -> 3.7802521 | E20: =player_metrics!O25 -> 0.32871757 | F20: 0
A21: =player_metrics!B19 -> Prerit Anand | B21: =player_metrics!C19 -> All-Rounder | C21: =raw_data!N19 -> 7.5 | D21: =player_metrics!N19 -> 3.6852174 | E21: =player_metrics!O19 -> 0.54194374 | F21: 0
A22: =player_metrics!B55 -> Pranav Wagh | B22: =player_metrics!C55 -> Batsman | C22: =raw_data!N55 -> 7.6 | D22: =player_metrics!N55 -> 1.2678615 | E22: =player_metrics!O55 -> 0.091213058 | F22: 1
A23: =player_metrics!B34 -> Manan Kapoor | B23: =player_metrics!C34 -> Batsman | C23: =raw_data!N34 -> 8.1 | D23: =player_metrics!N34 -> 1.2196455 | E23: =player_metrics!O34 -> 0.22175372 | F23: 0
A24: =player_metrics!B49 -> Ishaan Dhamija | B24: =player_metrics!C49 -> Batsman | C24: =raw_data!N49 -> 8.3 | D24: =player_metrics!N49 -> 1.2518943 | E24: =player_metrics!O49 -> 0.11922803 | F24: 0
A25: =player_metrics!B31 -> Harsh Daga | B25: =player_metrics!C31 -> Wicketkeeper | C25: =raw_data!N31 -> 8.4 | D25: =player_metrics!N31 -> 1.023205 | E25: =player_metrics!O31 -> 0.23795465 | F25: 0
A26: =player_metrics!B4 -> Varun Jaitley | B26: =player_metrics!C4 -> Bowler | C26: =raw_data!N4 -> 8.5 | D26: =player_metrics!N4 -> 9.306129 | E26: =player_metrics!O4 -> 1.5009885 | F26: 0
A27: =player_metrics!B11 -> Gagan Trivedi | B27: =player_metrics!C11 -> Bowler | C27: =raw_data!N11 -> 8.7 | D27: =player_metrics!N11 -> 9.7219866 | E27: =player_metrics!O11 -> 0.91716855 | F27: 0
A28: =player_metrics!B23 -> Amitesh Pillai | B28: =player_metrics!C23 -> All-Rounder | C28: =raw_data!N23 -> 8.9 | D28: =player_metrics!N23 -> 3.7980468 | E28: =player_metrics!O23 -> 0.36519681 | F28: 0
A29: =player_metrics!B60 -> Saket Bafna | B29: =player_metrics!C60 -> Wicketkeeper | C29: =raw_data!N60 -> 8.9 | D29: =player_metrics!N60 -> 1.1546018 | E29: =player_metrics!O60 -> 0.073076062 | F29: 0
A30: =player_metrics!B41 -> Uday Patwardhan | B30: =player_metrics!C41 -> Wicketkeeper | C30: =raw_data!N41 -> 9.1 | D30: =player_metrics!N41 -> 1.0184404 | E30: =player_metrics!O41 -> 0.16426458 | F30: 0
A31: =player_metrics!B9 -> Rahul Divate | B31: =player_metrics!C9 -> Bowler | C31: =raw_data!N9 -> 9.2 | D31: =player_metrics!N9 -> 9.4205683 | E31: =player_metrics!O9 -> 1.0584908 | F31: 0
A32: =player_metrics!B53 -> Aarav Shekhawat | B32: =player_metrics!C53 -> Batsman | C32: =raw_data!N53 -> 9.2 | D32: =player_metrics!N53 -> 1.3527343 | E32: =player_metrics!O53 -> 0.09329202 | F32: 0
A33: =player_metrics!B46 -> Piyush Kakkar | B33: =player_metrics!C46 -> Wicketkeeper | C33: =raw_data!N46 -> 9.3 | D33: =player_metrics!N46 -> 1.0975586 | E33: =player_metrics!O46 -> 0.13223597 | F33: 0
A34: =player_metrics!B18 -> Soham Borkar | B34: =player_metrics!C18 -> All-Rounder | C34: =raw_data!N18 -> 9.7 | D34: =player_metrics!N18 -> 3.5841271 | E34: =player_metrics!O18 -> 0.56890907 | F34: 0
A35: =player_metrics!B33 -> Harshil Mehta | B35: =player_metrics!C33 -> Batsman | C35: =raw_data!N33 -> 10.4 | D35: =player_metrics!N33 -> 1.0994705 | E35: =player_metrics!O33 -> 0.22905635 | F35: 0
A36: =player_metrics!B14 -> Arpit Bansal | B36: =player_metrics!C14 -> All-Rounder | C36: =raw_data!N14 -> 10.5 | D36: =player_metrics!N14 -> 3.7551441 | E36: =player_metrics!O14 -> 0.7221431 | F36: 0
A37: =player_metrics!B26 -> Harit Shah | B37: =player_metrics!C26 -> All-Rounder | C37: =raw_data!N26 -> 10.6 | D37: =player_metrics!N26 -> 3.8370637 | E37: =player_metrics!O26 -> 0.30944062 | F37: 0
A38: =player_metrics!B48 -> Lakshay Oberoi | B38: =player_metrics!C48 -> Wicketkeeper | C38: =raw_data!N48 -> 10.6 | D38: =player_metrics!N48 -> 1.0772721 | E38: =player_metrics!O48 -> 0.12104181 | F38: 0
A39: =player_metrics!B45 -> Karan Bhise | B39: =player_metrics!C45 -> Wicketkeeper | C39: =raw_data!N45 -> 10.9 | D39: =player_metrics!N45 -> 1.0112478 | E39: =player_metrics!O45 -> 0.13305893 | F39: 0
A40: =player_metrics!B29 -> Vikram Khurana | B40: =player_metrics!C29 -> All-Rounder | C40: =raw_data!N29 -> 11.2 | D40: =player_metrics!N29 -> 3.9232732 | E40: =player_metrics!O29 -> 0.26330692 | F40: 1
...

Sheet Dashboard
H1: player name | I1: auction_price | J1: impact_score
B2: Total Squad Cost | C2: =squad_selection!I3 -> 90 | E2: Batsmen | F2: =squad_selection!I4 -> 4 | H2: =player_metrics!B2 -> Neel Verma | I2: =raw_data!N2 -> 14.5 | J2: =player_metrics!N2 -> 8.8432792
B3: Team Impact Score | C3: =squad_selection!I10 -> 56.466574 | E3: Bowlers | F3: =squad_selection!I5 -> 4 | H3: =player_metrics!B3 -> Hemant Luniya | I3: =raw_data!N3 -> 12.2 | J3: =player_metrics!N3 -> 9.1178811
B4: Avg Impact per Player | C4: =C3/12 -> 4.7055478 | E4: All-Rounders | F4: =squad_selection!I6 -> 3 | H4: =player_metrics!B4 -> Varun Jaitley | I4: =raw_data!N4 -> 8.5 | J4: =player_metrics!N4 -> 9.306129
B5: Remaining Budget | C5: =90-C2 -> 0 | E5: Wicketkeepers | F5: =squad_selection!I7 -> 1 | H5: =player_metrics!B5 -> Yuvraj Mahadik | I5: =raw_data!N5 -> 6.2 | J5: =player_metrics!N5 -> 9.3429174
H6: =player_metrics!B6 -> Saurabh Pathak | I6: =raw_data!N6 -> 17.3 | J6: =player_metrics!N6 -> 9.1503376
H7: =player_metrics!B7 -> Mohit Deshpande | I7: =raw_data!N7 -> 5.5 | J7: =player_metrics!N7 -> 9.306129
H8: =player_metrics!B8 -> Tarun Sethi | I8: =raw_data!N8 -> 15.6 | J8: =player_metrics!N8 -> 9.6336785
H9: =player_metrics!B9 -> Rahul Divate | I9: =raw_data!N9 -> 9.2 | J9: =player_metrics!N9 -> 9.4205683
H10: =player_metrics!B10 -> Siddharth Kaulkar | I10: =raw_data!N10 -> 5.8 | J10: =player_metrics!N10 -> 9.609594
H11: =player_metrics!B11 -> Gagan Trivedi | I11: =raw_data!N11 -> 8.7 | J11: =player_metrics!N11 -> 9.7219866
H12: =player_metrics!B12 -> Keshav Rawat | I12: =raw_data!N12 -> 4.8 | J12: =player_metrics!N12 -> 9.8167234
H13: =player_metrics!B13 -> Arjun Bhalerao | I13: =raw_data!N13 -> 13.9 | J13: =player_metrics!N13 -> 9.5966288
H14: =player_metrics!B14 -> Arpit Bansal | I14: =raw_data!N14 -> 10.5 | J14: =player_metrics!N14 -> 3.7551441
H15: =player_metrics!B15 -> Ritwik Sahaal | I15: =raw_data!N15 -> 6.5 | J15: =player_metrics!N15 -> 9.1531757
H16: =player_metrics!B16 -> Laksh Nayak | I16: =raw_data!N16 -> 5.2 | J16: =player_metrics!N16 -> 9.4410095
H17: =player_metrics!B17 -> Parth Keni | I17: =raw_data!N17 -> 11.8 | J17: =player_metrics!N17 -> 9.3607384
... H61: =player_metrics!B61 -> Naman Luthra | I61: =raw_data!N61 -> 6.5 | J61: =player_metrics!N61 -> 1.1286219
